test_closest (__main__.TestExercice) ... FAIL
test_coordinates (__main__.TestExercice) ... ok
test_linear_values (__main__.TestExercice) ... ok

======================================================================
FAIL: test_closest (__main__.TestExercice)
----------------------------------------------------------------------
Traceback (most recent call last):
  File "test_exercice.py", line 45, in test_closest
    'Erreur dans le remplacement de caractère'
AssertionError: 0 != 3 : Erreur dans le remplacement de caractère

----------------------------------------------------------------------
Ran 3 tests in 0.001s

FAILED (failures=1)
